Workbook
Name base: [1]Feuil2!$B$4:$M$37

Sheet 👥 Personnel
A1: LISTE DU PERSONNEL - Saisir ici vos salariés
A3: ID | B3: Fonction à supprimer | C3: Nom | D3: Prénom | E3: Site | F3: Fonction | G3: Type de contrat | H3: Catégorie | I3: Coef | J3: Sexe | K3: Date Entree | L3: Date d'anc. | M3: Date de naissance | N3: Salaire Brut Mensuel (Base brut CP) | O3: Salaire Brut annuel | P3: Nb CP Acquis | Q3: Date de sortie théorique | R3: Salaire Brut de référence | S3: Provision CP | T3: Ancienneté (ans) réelle | U3: Age | V3: Salaire Annuel Total | W3: Préavis (mois) | X3: Ancienneté (ans) à la date théorique de sortie | Y3: Salarié Protégé | Z3: Situation familiale | AA3: Nb d'enfants | AB3: Charge de famille | AC3: Difficulté de reclassement | AD3: Nb de points | AE3: Commentaires | AF3: CSP (contrat de sécurisation professionnel) | AG3: INDEM LÉGALE | AH3: INDEM CONV. | AI3: COMPARAISON | AJ3: INDEM RETENUE | AK3: Majoration PSE | AL3: TOTAL INDEM | AM3: Préavis Calc (mois) | AN3: Indem Préavis Brut | AO3: CP Calc (jrs) | AP3: Indem CP | AQ3: COÛT Charges Patronales | AR3: COÛT TOTAL
A4: 3 | B4: Non | C4: BASTARD | D4: Gilles | E4: PUSIGNAN | F4: Manutentionnaire | G4: CDI | H4: Ouvrier | I4: 138M | J4: H | K4: 39153 | L4: 39153 | M4: 25026 | N4: 2320.54 | P4: 30.58 | Q4: =IF(UPPER(B4)="OUI",'📈 Dashboard'!$B$37,"") | R4: =MAX(N4,O4/12) -> 2320.54 | S4: 3223.72 | T4: =IF(L4="",(TODAY()-K4)/365.25,MAX((TODAY()-K4)/365.25,(TODAY()-L4)/365.25)) -> 19.011636 | U4: =IF(M4="","",(TODAY()-M4)/365.25) -> 57.689254 | V4: =N4*12 -> 27846.48 | W4: =IF(H4="Cadre",3,IF(H4="Haute maitrise",2,IF(OR(H4="Agent Maitrise",H4="Agent de maitrise"),IF(T4<2/12,0,IF(T4<2,1,2)),IF(OR(H4="Ouvrier"),IF(T4<6/12,1/4,IF(T4<2,1,2)),IF(OR(H4="Employe",H4="Employé"),IF(T4<1/12,0,IF(T4<2,1,2)),2))))) -> 2 | X4: =IF(Q4="",T4,(Q4-K4)/365.25) -> 19.011636 | AG4: =IF(TPersonnel[[#This Row],[Fonction à supprimer]]="NON",0,IF(TPersonnel[[#This Row],[Ancienneté (ans) à la date théorique de sortie]]<0.67,0,IF(TPersonnel[[#This Row],[Ancienneté (ans) à la date théorique de sortie]]<=10,TPersonnel[[#This Row],[Ancienneté (ans) à la date théorique de sortie]]*TPersonnel[[#This Row],[Salaire Brut de référence]]/4,(10*TPersonnel[[#This Row],[Salaire Brut de référence]]/4+(TPersonnel[[#This Row],[Ancienneté (ans) à la date théorique de sortie]]-10)*TPersonnel[[#This Row],[Salaire Brut de référence]]/3)))) -> 0 | AH4: =IF(UPPER(TPersonnel[[#This Row],[Fonction à supprimer]])="NON",0,IF(TPersonnel[[#This Row],[Ancienneté (ans) à la date théorique de sortie]]<1,0,IF(OR(TPersonnel[[#This Row],[Catégorie]]="Ouvrier",TPersonnel[[#This Row],[Catégorie]]="Employe",TPersonnel[[#This Row],[Catégorie]]="Employé"),IF(TPersonnel[[#This Row],[Ancienneté (ans) à la date théorique de sortie]]<3,TPersonnel[[#This Row],[Ancienneté (ans) à la date théorique de sortie]]*TPersonnel[[#This Row],[Salaire Brut de référence]]/10,TPersonnel[[#This Row],[Ancienneté (ans) à la date théorique de sortie]]*TPersonnel[[#This Row],[Salaire Brut de référence]]*2/10),IF(OR(TPersonnel[[#This Row],[Catégorie]]="Agent Maitrise",TPersonnel[[#This Row],[Catégorie]]="Agent de maitrise",TPersonnel[[#This Row],[Catégorie]]="Haute maitrise"),IF(TPersonnel[[#This Row],[Ancienneté (ans) à la date théorique de sortie]]<3,TPersonnel[[#This Row],[Ancienneté (ans) à la date théorique de sortie]]*TPersonnel[[#This Row],[Salaire Brut de référence]]/10,TPersonnel[[#This Row],[Ancienneté (ans) à la date théorique de sortie]]*TPersonnel[[#This Row],[Salaire Brut de référence]]*3/10),IF(TPersonnel[[#This Row],[Catégorie]]="Cadre",IF(TPersonnel[[#This Row],[Ancienneté (ans) à la date théorique de sortie]]<3,0,TPersonnel[[#This Row],[Ancienneté (ans) à la date théorique de sortie]]*TPersonnel[[#This Row],[Salaire Brut de référence]]*4/10),0))))) -> 0 | AI4: =IF(TPersonnel[[#This Row],[INDEM LÉGALE]]=0,"",IF(TPersonnel[[#This Row],[INDEM LÉGALE]]>TPersonnel[[#This Row],[INDEM CONV.]],"LEGAL","CONVENTIONNEL")) | AJ4: =MAX(TPersonnel[[#This Row],[INDEM LÉGALE]],TPersonnel[[#This Row],[INDEM CONV.]]) -> 0 | AK4: =TPersonnel[[#This Row],[INDEM RETENUE]]*'⚙️ Parametres'!$B$5 -> 0 | AL4: =TPersonnel[[#This Row],[INDEM RETENUE]]+TPersonnel[[#This Row],[Majoration PSE]] -> 0 | AM4: =IF(UPPER(TPersonnel[[#This Row],[Fonction à supprimer]])="NON",0,IF(OR(TPersonnel[[#This Row],[Catégorie]]="Cadre"),3,IF(TPersonnel[[#This Row],[Catégorie]]="Haute maitrise",2,IF(OR(TPersonnel[[#This Row],[Catégorie]]="Agent Maitrise",TPersonnel[[#This Row],[Catégorie]]="Agent de maitrise"),IF(TPersonnel[[#This Row],[Ancienneté (ans) à la date théorique de sortie]]<2/12,0,IF(TPersonnel[[#This Row],[Ancienneté (ans) à la date théorique de sortie]]<2,1,2)),IF(OR(TPersonnel[[#This Row],[Catégorie]]="Ouvrier",TPersonnel[[#This Row],[Catégorie]]="Employe",TPersonnel[[#This Row],[Catégorie]]="Employé"),IF(TPersonnel[[#This Row],[Ancienneté (ans) à la date théorique de sortie]]<6/12,IF(TPersonnel[[#This Row],[Catégorie]]="Ouvrier",1/4,IF(TPersonnel[[#This Row],[Ancienneté (ans) à la date théorique de sortie]]<1/12,0,1)),IF(TPersonnel[[#This Row],[Ancienneté (ans) à la date théorique de sortie]]<2,1,2)),2))))) -> 0 | AN4: =IF(UPPER(TPersonnel[[#This Row],[Fonction à supprimer]])="NON",0,TPersonnel[[#This Row],[Préavis Calc (mois)]]*TPersonnel[[#This Row],[Salaire Brut de référence]]) -> 0 | AO4: =IF(TPersonnel[[#This Row],[Fonction à supprimer]]="NON",0,TPersonnel[[#This Row],[Nb CP Acquis]]+TPersonnel[[#This Row],[Préavis Calc (mois)]]*2.08) -> 0 | AP4: =TPersonnel[[#This Row],[CP Calc (jrs)]]*TPersonnel[[#This Row],[Salaire Brut de référence]]/21.67 -> 0 | AQ4: =IF(UPPER(TPersonnel[[#This Row],[Fonction à supprimer]])="NON",0,_xlfn.LET(_xlpm.taux,IF(TPersonnel[[#This Row],[Catégorie]]="Ouvrier",'📈 Dashboard'!$B$32,IF(TPersonnel[[#This Row],[Catégorie]]="Cadre",'📈 Dashboard'!$B$34,'📈 Dashboard'!$B$33)),_xlpm.csp,UPPER(TPersonnel[[#This Row],[CSP (contrat de sécurisation professionnel)]])="OUI",IF(AND(_xlpm.csp,TPersonnel[[#This Row],[Ancienneté (ans) à la date théorique de sortie]]>=1),MIN(TPersonnel[[#This Row],[Préavis Calc (mois)]],3)*TPersonnel[[#This Row],[Salaire Brut de référence]]*(_xlpm.taux+'⚙️ Parametres'!$B$11)+IF(TPersonnel[[#This Row],[Préavis Calc (mois)]]>3,(TPersonnel[[#This Row],[Préavis Calc (mois)]]-3)*TPersonnel[[#This Row],[Salaire Brut de référence]]*_xlpm.taux,0)+TPersonnel[[#This Row],[Indem CP]]*_xlpm.taux,IF(_xlpm.csp,TPersonnel[[#This Row],[Indem CP]]*_xlpm.taux,(TPersonnel[[#This Row],[Indem Préavis Brut]]+TPersonnel[[#This Row],[Indem CP]])*_xlpm.taux)))) -> 0 | AR4: =TPersonnel[[#This Row],[TOTAL INDEM]]+TPersonnel[[#This Row],[Indem Préavis Brut]]+TPersonnel[[#This Row],[Indem CP]]+TPersonnel[[#This Row],[COÛT Charges Patronales]] -> 0
A5: 8 | B5: Non | C5: GERARD | D5: Bruno | E5: VALENCE | F5: Chauffeur PL | G5: CDI | H5: Ouvrier | I5: 138M | J5: H | K5: 35128 | L5: 35128 | M5: 27781 | N5: 2635.89 | P5: 27.08 | Q5: =IF(UPPER(B5)="OUI",'📈 Dashboard'!$B$37,"") | R5: =MAX(N5,O5/12) -> 2635.89 | S5: 3664.22 | T5: =IF(L5="",(TODAY()-K5)/365.25,MAX((TODAY()-K5)/365.25,(TODAY()-L5)/365.25)) -> 30.031485 | U5: =IF(M5="","",(TODAY()-M5)/365.25) -> 50.146475 | V5: =N5*12 -> 31630.68 | W5: =IF(H5="Cadre",3,IF(H5="Haute maitrise",2,IF(OR(H5="Agent Maitrise",H5="Agent de maitrise"),IF(T5<2/12,0,IF(T5<2,1,2)),IF(OR(H5="Ouvrier"),IF(T5<6/12,1/4,IF(T5<2,1,2)),IF(OR(H5="Employe",H5="Employé"),IF(T5<1/12,0,IF(T5<2,1,2)),2))))) -> 2 | X5: =IF(Q5="",T5,(Q5-K5)/365.25) -> 30.031485 | AG5: =IF(TPersonnel[[#This Row],[Fonction à supprimer]]="NON",0,IF(TPersonnel[[#This Row],[Ancienneté (ans) à la date théorique de sortie]]<0.67,0,IF(TPersonnel[[#This Row],[Ancienneté (ans) à la date théorique de sortie]]<=10,TPersonnel[[#This Row],[Ancienneté (ans) à la date théorique de sortie]]*TPersonnel[[#This Row],[Salaire Brut de référence]]/4,(10*TPersonnel[[#This Row],[Salaire Brut de référence]]/4+(TPersonnel[[#This Row],[Ancienneté (ans) à la date théorique de sortie]]-10)*TPersonnel[[#This Row],[Salaire Brut de référence]]/3)))) -> 0 | AH5: =IF(UPPER(TPersonnel[[#This Row],[Fonction à supprimer]])="NON",0,IF(TPersonnel[[#This Row],[Ancienneté (ans) à la date théorique de sortie]]<1,0,IF(OR(TPersonnel[[#This Row],[Catégorie]]="Ouvrier",TPersonnel[[#This Row],[Catégorie]]="Employe",TPersonnel[[#This Row],[Catégorie]]="Employé"),IF(TPersonnel[[#This Row],[Ancienneté (ans) à la date théorique de sortie]]<3,TPersonnel[[#This Row],[Ancienneté (ans) à la date théorique de sortie]]*TPersonnel[[#This Row],[Salaire Brut de référence]]/10,TPersonnel[[#This Row],[Ancienneté (ans) à la date théorique de sortie]]*TPersonnel[[#This Row],[Salaire Brut de référence]]*2/10),IF(OR(TPersonnel[[#This Row],[Catégorie]]="Agent Maitrise",TPersonnel[[#This Row],[Catégorie]]="Agent de maitrise",TPersonnel[[#This Row],[Catégorie]]="Haute maitrise"),IF(TPersonnel[[#This Row],[Ancienneté (ans) à la date théorique de sortie]]<3,TPersonnel[[#This Row],[Ancienneté (ans) à la date théorique de sortie]]*TPersonnel[[#This Row],[Salaire Brut de référence]]/10,TPersonnel[[#This Row],[Ancienneté (ans) à la date théorique de sortie]]*TPersonnel[[#This Row],[Salaire Brut de référence]]*3/10),IF(TPersonnel[[#This Row],[Catégorie]]="Cadre",IF(TPersonnel[[#This Row],[Ancienneté (ans) à la date théorique de sortie]]<3,0,TPersonnel[[#This Row],[Ancienneté (ans) à la date théorique de sortie]]*TPersonnel[[#This Row],[Salaire Brut de référence]]*4/10),0))))) -> 0 | AI5: =IF(TPersonnel[[#This Row],[INDEM LÉGALE]]=0,"",IF(TPersonnel[[#This Row],[INDEM LÉGALE]]>TPersonnel[[#This Row],[INDEM CONV.]],"LEGAL","CONVENTIONNEL")) | AJ5: =MAX(TPersonnel[[#This Row],[INDEM LÉGALE]],TPersonnel[[#This Row],[INDEM CONV.]]) -> 0 | AK5: =TPersonnel[[#This Row],[INDEM RETENUE]]*'⚙️ Parametres'!$B$5 -> 0 | AL5: =TPersonnel[[#This Row],[INDEM RETENUE]]+TPersonnel[[#This Row],[Majoration PSE]] -> 0 | AM5: =IF(UPPER(TPersonnel[[#This Row],[Fonction à supprimer]])="NON",0,IF(OR(TPersonnel[[#This Row],[Catégorie]]="Cadre"),3,IF(TPersonnel[[#This Row],[Catégorie]]="Haute maitrise",2,IF(OR(TPersonnel[[#This Row],[Catégorie]]="Agent Maitrise",TPersonnel[[#This Row],[Catégorie]]="Agent de maitrise"),IF(TPersonnel[[#This Row],[Ancienneté (ans) à la date théorique de sortie]]<2/12,0,IF(TPersonnel[[#This Row],[Ancienneté (ans) à la date théorique de sortie]]<2,1,2)),IF(OR(TPersonnel[[#This Row],[Catégorie]]="Ouvrier",TPersonnel[[#This Row],[Catégorie]]="Employe",TPersonnel[[#This Row],[Catégorie]]="Employé"),IF(TPersonnel[[#This Row],[Ancienneté (ans) à la date théorique de sortie]]<6/12,IF(TPersonnel[[#This Row],[Catégorie]]="Ouvrier",1/4,IF(TPersonnel[[#This Row],[Ancienneté (ans) à la date théorique de sortie]]<1/12,0,1)),IF(TPersonnel[[#This Row],[Ancienneté (ans) à la date théorique de sortie]]<2,1,2)),2))))) -> 0 | AN5: =IF(UPPER(TPersonnel[[#This Row],[Fonction à supprimer]])="NON",0,TPersonnel[[#This Row],[Préavis Calc (mois)]]*TPersonnel[[#This Row],[Salaire Brut de référence]]) -> 0 | AO5: =IF(TPersonnel[[#This Row],[Fonction à supprimer]]="NON",0,TPersonnel[[#This Row],[Nb CP Acquis]]+TPersonnel[[#This Row],[Préavis Calc (mois)]]*2.08) -> 0 | AP5: =TPersonnel[[#This Row],[CP Calc (jrs)]]*TPersonnel[[#This Row],[Salaire Brut de référence]]/21.67 -> 0 | AQ5: =IF(UPPER(TPersonnel[[#This Row],[Fonction à supprimer]])="NON",0,_xlfn.LET(_xlpm.taux,IF(TPersonnel[[#This Row],[Catégorie]]="Ouvrier",'📈 Dashboard'!$B$32,IF(TPersonnel[[#This Row],[Catégorie]]="Cadre",'📈 Dashboard'!$B$34,'📈 Dashboard'!$B$33)),_xlpm.csp,UPPER(TPersonnel[[#This Row],[CSP (contrat de sécurisation professionnel)]])="OUI",IF(AND(_xlpm.csp,TPersonnel[[#This Row],[Ancienneté (ans) à la date théorique de sortie]]>=1),MIN(TPersonnel[[#This Row],[Préavis Calc (mois)]],3)*TPersonnel[[#This Row],[Salaire Brut de référence]]*(_xlpm.taux+'⚙️ Parametres'!$B$11)+IF(TPersonnel[[#This Row],[Préavis Calc (mois)]]>3,(TPersonnel[[#This Row],[Préavis Calc (mois)]]-3)*TPersonnel[[#This Row],[Salaire Brut de référence]]*_xlpm.taux,0)+TPersonnel[[#This Row],[Indem CP]]*_xlpm.taux,IF(_xlpm.csp,TPersonnel[[#This Row],[Indem CP]]*_xlpm.taux,(TPersonnel[[#This Row],[Indem Préavis Brut]]+TPersonnel[[#This Row],[Indem CP]])*_xlpm.taux)))) -> 0 | AR5: =TPersonnel[[#This Row],[TOTAL INDEM]]+TPersonnel[[#This Row],[Indem Préavis Brut]]+TPersonnel[[#This Row],[Indem CP]]+TPersonnel[[#This Row],[COÛT Charges Patronales]] -> 0
A6: 9 | B6: Non | C6: GERARD | D6: Pascal | E6: PUSIGNAN | F6: Chef de Quai Temp | G6: CDI | H6: Ouvrier | I6: 150M | J6: H | K6: 35541 | L6: 35541 | M6: 28477 | N6: 2687.99 | P6: 57.08 | Q6: =IF(UPPER(B6)="OUI",'📈 Dashboard'!$B$37,"") | R6: =MAX(N6,O6/12) -> 2687.99 | S6: 7424.6 | T6: =IF(L6="",(TODAY()-K6)/365.25,MAX((TODAY()-K6)/365.25,(TODAY()-L6)/365.25)) -> 28.900753 | U6: =IF(M6="","",(TODAY()-M6)/365.25) -> 48.240931 | V6: =N6*12 -> 32255.88 | W6: =IF(H6="Cadre",3,IF(H6="Haute maitrise",2,IF(OR(H6="Agent Maitrise",H6="Agent de maitrise"),IF(T6<2/12,0,IF(T6<2,1,2)),IF(OR(H6="Ouvrier"),IF(T6<6/12,1/4,IF(T6<2,1,2)),IF(OR(H6="Employe",H6="Employé"),IF(T6<1/12,0,IF(T6<2,1,2)),2))))) -> 2 | X6: =IF(Q6="",T6,(Q6-K6)/365.25) -> 28.900753 | AG6: =IF(TPersonnel[[#This Row],[Fonction à supprimer]]="NON",0,IF(TPersonnel[[#This Row],[Ancienneté (ans) à la date théorique de sortie]]<0.67,0,IF(TPersonnel[[#This Row],[Ancienneté (ans) à la date théorique de sortie]]<=10,TPersonnel[[#This Row],[Ancienneté (ans) à la date théorique de sortie]]*TPersonnel[[#This Row],[Salaire Brut de référence]]/4,(10*TPersonnel[[#This Row],[Salaire Brut de référence]]/4+(TPersonnel[[#This Row],[Ancienneté (ans) à la date théorique de sortie]]-10)*TPersonnel[[#This Row],[Salaire Brut de référence]]/3)))) -> 0 | AH6: =IF(UPPER(TPersonnel[[#This Row],[Fonction à supprimer]])="NON",0,IF(TPersonnel[[#This Row],[Ancienneté (ans) à la date théorique de sortie]]<1,0,IF(OR(TPersonnel[[#This Row],[Catégorie]]="Ouvrier",TPersonnel[[#This Row],[Catégorie]]="Employe",TPersonnel[[#This Row],[Catégorie]]="Employé"),IF(TPersonnel[[#This Row],[Ancienneté (ans) à la date théorique de sortie]]<3,TPersonnel[[#This Row],[Ancienneté (ans) à la date théorique de sortie]]*TPersonnel[[#This Row],[Salaire Brut de référence]]/10,TPersonnel[[#This Row],[Ancienneté (ans) à la date théorique de sortie]]*TPersonnel[[#This Row],[Salaire Brut de référence]]*2/10),IF(OR(TPersonnel[[#This Row],[Catégorie]]="Agent Maitrise",TPersonnel[[#This Row],[Catégorie]]="Agent de maitrise",TPersonnel[[#This Row],[Catégorie]]="Haute maitrise"),IF(TPersonnel[[#This Row],[Ancienneté (ans) à la date théorique de sortie]]<3,TPersonnel[[#This Row],[Ancienneté (ans) à la date théorique de sortie]]*TPersonnel[[#This Row],[Salaire Brut de référence]]/10,TPersonnel[[#This Row],[Ancienneté (ans) à la date théorique de sortie]]*TPersonnel[[#This Row],[Salaire Brut de référence]]*3/10),IF(TPersonnel[[#This Row],[Catégorie]]="Cadre",IF(TPersonnel[[#This Row],[Ancienneté (ans) à la date théorique de sortie]]<3,0,TPersonnel[[#This Row],[Ancienneté (ans) à la date théorique de sortie]]*TPersonnel[[#This Row],[Salaire Brut de référence]]*4/10),0))))) -> 0 | AI6: =IF(TPersonnel[[#This Row],[INDEM LÉGALE]]=0,"",IF(TPersonnel[[#This Row],[INDEM LÉGALE]]>TPersonnel[[#This Row],[INDEM CONV.]],"LEGAL","CONVENTIONNEL")) | AJ6: =MAX(TPersonnel[[#This Row],[INDEM LÉGALE]],TPersonnel[[#This Row],[INDEM CONV.]]) -> 0 | AK6: =TPersonnel[[#This Row],[INDEM RETENUE]]*'⚙️ Parametres'!$B$5 -> 0 | AL6: =TPersonnel[[#This Row],[INDEM RETENUE]]+TPersonnel[[#This Row],[Majoration PSE]] -> 0 | AM6: =IF(UPPER(TPersonnel[[#This Row],[Fonction à supprimer]])="NON",0,IF(OR(TPersonnel[[#This Row],[Catégorie]]="Cadre"),3,IF(TPersonnel[[#This Row],[Catégorie]]="Haute maitrise",2,IF(OR(TPersonnel[[#This Row],[Catégorie]]="Agent Maitrise",TPersonnel[[#This Row],[Catégorie]]="Agent de maitrise"),IF(TPersonnel[[#This Row],[Ancienneté (ans) à la date théorique de sortie]]<2/12,0,IF(TPersonnel[[#This Row],[Ancienneté (ans) à la date théorique de sortie]]<2,1,2)),IF(OR(TPersonnel[[#This Row],[Catégorie]]="Ouvrier",TPersonnel[[#This Row],[Catégorie]]="Employe",TPersonnel[[#This Row],[Catégorie]]="Employé"),IF(TPersonnel[[#This Row],[Ancienneté (ans) à la date théorique de sortie]]<6/12,IF(TPersonnel[[#This Row],[Catégorie]]="Ouvrier",1/4,IF(TPersonnel[[#This Row],[Ancienneté (ans) à la date théorique de sortie]]<1/12,0,1)),IF(TPersonnel[[#This Row],[Ancienneté (ans) à la date théorique de sortie]]<2,1,2)),2))))) -> 0 | AN6: =IF(UPPER(TPersonnel[[#This Row],[Fonction à supprimer]])="NON",0,TPersonnel[[#This Row],[Préavis Calc (mois)]]*TPersonnel[[#This Row],[Salaire Brut de référence]]) -> 0 | AO6: =IF(TPersonnel[[#This Row],[Fonction à supprimer]]="NON",0,TPersonnel[[#This Row],[Nb CP Acquis]]+TPersonnel[[#This Row],[Préavis Calc (mois)]]*2.08) -> 0 | AP6: =TPersonnel[[#This Row],[CP Calc (jrs)]]*TPersonnel[[#This Row],[Salaire Brut de référence]]/21.67 -> 0 | AQ6: =IF(UPPER(TPersonnel[[#This Row],[Fonction à supprimer]])="NON",0,_xlfn.LET(_xlpm.taux,IF(TPersonnel[[#This Row],[Catégorie]]="Ouvrier",'📈 Dashboard'!$B$32,IF(TPersonnel[[#This Row],[Catégorie]]="Cadre",'📈 Dashboard'!$B$34,'📈 Dashboard'!$B$33)),_xlpm.csp,UPPER(TPersonnel[[#This Row],[CSP (contrat de sécurisation professionnel)]])="OUI",IF(AND(_xlpm.csp,TPersonnel[[#This Row],[Ancienneté (ans) à la date théorique de sortie]]>=1),MIN(TPersonnel[[#This Row],[Préavis Calc (mois)]],3)*TPersonnel[[#This Row],[Salaire Brut de référence]]*(_xlpm.taux+'⚙️ Parametres'!$B$11)+IF(TPersonnel[[#This Row],[Préavis Calc (mois)]]>3,(TPersonnel[[#This Row],[Préavis Calc (mois)]]-3)*TPersonnel[[#This Row],[Salaire Brut de référence]]*_xlpm.taux,0)+TPersonnel[[#This Row],[Indem CP]]*_xlpm.taux,IF(_xlpm.csp,TPersonnel[[#This Row],[Indem CP]]*_xlpm.taux,(TPersonnel[[#This Row],[Indem Préavis Brut]]+TPersonnel[[#This Row],[Indem CP]])*_xlpm.taux)))) -> 0 | AR6: =TPersonnel[[#This Row],[TOTAL INDEM]]+TPersonnel[[#This Row],[Indem Préavis Brut]]+TPersonnel[[#This Row],[Indem CP]]+TPersonnel[[#This Row],[COÛT Charges Patronales]] -> 0
A7: 18 | B7: Non | C7: PAVARD | D7: Joel | E7: ROGNAC | F7: Chauffeur PL | G7: CDI | H7: Ouvrier | I7: 150M | J7: H | K7: 37734 | L7: 37734 | M7: 23348 | N7: 3098.37 | P7: 22.08 | Q7: =IF(UPPER(B7)="OUI",'📈 Dashboard'!$B$37,"") | R7: =MAX(N7,O7/12) -> 3098.37 | S7: 3362.77 | T7: =IF(L7="",(TODAY()-K7)/365.25,MAX((TODAY()-K7)/365.25,(TODAY()-L7)/365.25)) -> 22.896646 | U7: =IF(M7="","",(TODAY()-M7)/365.25) -> 62.283368 | V7: =N7*12 -> 37180.44 | W7: =IF(H7="Cadre",3,IF(H7="Haute maitrise",2,IF(OR(H7="Agent Maitrise",H7="Agent de maitrise"),IF(T7<2/12,0,IF(T7<2,1,2)),IF(OR(H7="Ouvrier"),IF(T7<6/12,1/4,IF(T7<2,1,2)),IF(OR(H7="Employe",H7="Employé"),IF(T7<1/12,0,IF(T7<2,1,2)),2))))) -> 2 | X7: =IF(Q7="",T7,(Q7-K7)/365.25) -> 22.896646 | AG7: =IF(TPersonnel[[#This Row],[Fonction à supprimer]]="NON",0,IF(TPersonnel[[#This Row],[Ancienneté (ans) à la date théorique de sortie]]<0.67,0,IF(TPersonnel[[#This Row],[Ancienneté (ans) à la date théorique de sortie]]<=10,TPersonnel[[#This Row],[Ancienneté (ans) à la date théorique de sortie]]*TPersonnel[[#This Row],[Salaire Brut de référence]]/4,(10*TPersonnel[[#This Row],[Salaire Brut de référence]]/4+(TPersonnel[[#This Row],[Ancienneté (ans) à la date théorique de sortie]]-10)*TPersonnel[[#This Row],[Salaire Brut de référence]]/3)))) -> 0 | AH7: =IF(UPPER(TPersonnel[[#This Row],[Fonction à supprimer]])="NON",0,IF(TPersonnel[[#This Row],[Ancienneté (ans) à la date théorique de sortie]]<1,0,IF(OR(TPersonnel[[#This Row],[Catégorie]]="Ouvrier",TPersonnel[[#This Row],[Catégorie]]="Employe",TPersonnel[[#This Row],[Catégorie]]="Employé"),IF(TPersonnel[[#This Row],[Ancienneté (ans) à la date théorique de sortie]]<3,TPersonnel[[#This Row],[Ancienneté (ans) à la date théorique de sortie]]*TPersonnel[[#This Row],[Salaire Brut de référence]]/10,TPersonnel[[#This Row],[Ancienneté (ans) à la date théorique de sortie]]*TPersonnel[[#This Row],[Salaire Brut de référence]]*2/10),IF(OR(TPersonnel[[#This Row],[Catégorie]]="Agent Maitrise",TPersonnel[[#This Row],[Catégorie]]="Agent de maitrise",TPersonnel[[#This Row],[Catégorie]]="Haute maitrise"),IF(TPersonnel[[#This Row],[Ancienneté (ans) à la date théorique de sortie]]<3,TPersonnel[[#This Row],[Ancienneté (ans) à la date théorique de sortie]]*TPersonnel[[#This Row],[Salaire Brut de référence]]/10,TPersonnel[[#This Row],[Ancienneté (ans) à la date théorique de sortie]]*TPersonnel[[#This Row],[Salaire Brut de référence]]*3/10),IF(TPersonnel[[#This Row],[Catégorie]]="Cadre",IF(TPersonnel[[#This Row],[Ancienneté (ans) à la date théorique de sortie]]<3,0,TPersonnel[[#This Row],[Ancienneté (ans) à la date théorique de sortie]]*TPersonnel[[#This Row],[Salaire Brut de référence]]*4/10),0))))) -> 0 | AI7: =IF(TPersonnel[[#This Row],[INDEM LÉGALE]]=0,"",IF(TPersonnel[[#This Row],[INDEM LÉGALE]]>TPersonnel[[#This Row],[INDEM CONV.]],"LEGAL","CONVENTIONNEL")) | AJ7: =MAX(TPersonnel[[#This Row],[INDEM LÉGALE]],TPersonnel[[#This Row],[INDEM CONV.]]) -> 0 | AK7: =TPersonnel[[#This Row],[INDEM RETENUE]]*'⚙️ Parametres'!$B$5 -> 0 | AL7: =TPersonnel[[#This Row],[INDEM RETENUE]]+TPersonnel[[#This Row],[Majoration PSE]] -> 0 | AM7: =IF(UPPER(TPersonnel[[#This Row],[Fonction à supprimer]])="NON",0,IF(OR(TPersonnel[[#This Row],[Catégorie]]="Cadre"),3,IF(TPersonnel[[#This Row],[Catégorie]]="Haute maitrise",2,IF(OR(TPersonnel[[#This Row],[Catégorie]]="Agent Maitrise",TPersonnel[[#This Row],[Catégorie]]="Agent de maitrise"),IF(TPersonnel[[#This Row],[Ancienneté (ans) à la date théorique de sortie]]<2/12,0,IF(TPersonnel[[#This Row],[Ancienneté (ans) à la date théorique de sortie]]<2,1,2)),IF(OR(TPersonnel[[#This Row],[Catégorie]]="Ouvrier",TPersonnel[[#This Row],[Catégorie]]="Employe",TPersonnel[[#This Row],[Catégorie]]="Employé"),IF(TPersonnel[[#This Row],[Ancienneté (ans) à la date théorique de sortie]]<6/12,IF(TPersonnel[[#This Row],[Catégorie]]="Ouvrier",1/4,IF(TPersonnel[[#This Row],[Ancienneté (ans) à la date théorique de sortie]]<1/12,0,1)),IF(TPersonnel[[#This Row],[Ancienneté (ans) à la date théorique de sortie]]<2,1,2)),2))))) -> 0 | AN7: =IF(UPPER(TPersonnel[[#This Row],[Fonction à supprimer]])="NON",0,TPersonnel[[#This Row],[Préavis Calc (mois)]]*TPersonnel[[#This Row],[Salaire Brut de référence]]) -> 0 | AO7: =IF(TPersonnel[[#This Row],[Fonction à supprimer]]="NON",0,TPersonnel[[#This Row],[Nb CP Acquis]]+TPersonnel[[#This Row],[Préavis Calc (mois)]]*2.08) -> 0 | AP7: =TPersonnel[[#This Row],[CP Calc (jrs)]]*TPersonnel[[#This Row],[Salaire Brut de référence]]/21.67 -> 0 | AQ7: =IF(UPPER(TPersonnel[[#This Row],[Fonction à supprimer]])="NON",0,_xlfn.LET(_xlpm.taux,IF(TPersonnel[[#This Row],[Catégorie]]="Ouvrier",'📈 Dashboard'!$B$32,IF(TPersonnel[[#This Row],[Catégorie]]="Cadre",'📈 Dashboard'!$B$34,'📈 Dashboard'!$B$33)),_xlpm.csp,UPPER(TPersonnel[[#This Row],[CSP (contrat de sécurisation professionnel)]])="OUI",IF(AND(_xlpm.csp,TPersonnel[[#This Row],[Ancienneté (ans) à la date théorique de sortie]]>=1),MIN(TPersonnel[[#This Row],[Préavis Calc (mois)]],3)*TPersonnel[[#This Row],[Salaire Brut de référence]]*(_xlpm.taux+'⚙️ Parametres'!$B$11)+IF(TPersonnel[[#This Row],[Préavis Calc (mois)]]>3,(TPersonnel[[#This Row],[Préavis Calc (mois)]]-3)*TPersonnel[[#This Row],[Salaire Brut de référence]]*_xlpm.taux,0)+TPersonnel[[#This Row],[Indem CP]]*_xlpm.taux,IF(_xlpm.csp,TPersonnel[[#This Row],[Indem CP]]*_xlpm.taux,(TPersonnel[[#This Row],[Indem Préavis Brut]]+TPersonnel[[#This Row],[Indem CP]])*_xlpm.taux)))) -> 0 | AR7: =TPersonnel[[#This Row],[TOTAL INDEM]]+TPersonnel[[#This Row],[Indem Préavis Brut]]+TPersonnel[[#This Row],[Indem CP]]+TPersonnel[[#This Row],[COÛT Charges Patronales]] -> 0
A8: 19 | B8: Non | C8: MOKRANI | D8: Eric | E8: ROGNAC | F8: Chauffeur PL | G8: CDI | H8: Ouvrier | I8: 150M | J8: H | K8: 36026 | L8: 36026 | M8: 26580 | N8: 3238.84 | P8: 24.58 | Q8: =IF(UPPER(B8)="OUI",'📈 Dashboard'!$B$37,"") | R8: =MAX(N8,O8/12) -> 3238.84 | S8: 3815.22 | T8: =IF(L8="",(TODAY()-K8)/365.25,MAX((TODAY()-K8)/365.25,(TODAY()-L8)/365.25)) -> 27.572895 | U8: =IF(M8="","",(TODAY()-M8)/365.25) -> 53.434634 | V8: =N8*12 -> 38866.08 | W8: =IF(H8="Cadre",3,IF(H8="Haute maitrise",2,IF(OR(H8="Agent Maitrise",H8="Agent de maitrise"),IF(T8<2/12,0,IF(T8<2,1,2)),IF(OR(H8="Ouvrier"),IF(T8<6/12,1/4,IF(T8<2,1,2)),IF(OR(H8="Employe",H8="Employé"),IF(T8<1/12,0,IF(T8<2,1,2)),2))))) -> 2 | X8: =IF(Q8="",T8,(Q8-K8)/365.25) -> 27.572895 | AG8: =IF(TPersonnel[[#This Row],[Fonction à supprimer]]="NON",0,IF(TPersonnel[[#This Row],[Ancienneté (ans) à la date théorique de sortie]]<0.67,0,IF(TPersonnel[[#This Row],[Ancienneté (ans) à la date théorique de sortie]]<=10,TPersonnel[[#This Row],[Ancienneté (ans) à la date théorique de sortie]]*TPersonnel[[#This Row],[Salaire Brut de référence]]/4,(10*TPersonnel[[#This Row],[Salaire Brut de référence]]/4+(TPersonnel[[#This Row],[Ancienneté (ans) à la date théorique de sortie]]-10)*TPersonnel[[#This Row],[Salaire Brut de référence]]/3)))) -> 0 | AH8: =IF(UPPER(TPersonnel[[#This Row],[Fonction à supprimer]])="NON",0,IF(TPersonnel[[#This Row],[Ancienneté (ans) à la date théorique de sortie]]<1,0,IF(OR(TPersonnel[[#This Row],[Catégorie]]="Ouvrier",TPersonnel[[#This Row],[Catégorie]]="Employe",TPersonnel[[#This Row],[Catégorie]]="Employé"),IF(TPersonnel[[#This Row],[Ancienneté (ans) à la date théorique de sortie]]<3,TPersonnel[[#This Row],[Ancienneté (ans) à la date théorique de sortie]]*TPersonnel[[#This Row],[Salaire Brut de référence]]/10,TPersonnel[[#This Row],[Ancienneté (ans) à la date théorique de sortie]]*TPersonnel[[#This Row],[Salaire Brut de référence]]*2/10),IF(OR(TPersonnel[[#This Row],[Catégorie]]="Agent Maitrise",TPersonnel[[#This Row],[Catégorie]]="Agent de maitrise",TPersonnel[[#This Row],[Catégorie]]="Haute maitrise"),IF(TPersonnel[[#This Row],[Ancienneté (ans) à la date théorique de sortie]]<3,TPersonnel[[#This Row],[Ancienneté (ans) à la date théorique de sortie]]*TPersonnel[[#This Row],[Salaire Brut de référence]]/10,TPersonnel[[#This Row],[Ancienneté (ans) à la date théorique de sortie]]*TPersonnel[[#This Row],[Salaire Brut de référence]]*3/10),IF(TPersonnel[[#This Row],[Catégorie]]="Cadre",IF(TPersonnel[[#This Row],[Ancienneté (ans) à la date théorique de sortie]]<3,0,TPersonnel[[#This Row],[Ancienneté (ans) à la date théorique de sortie]]*TPersonnel[[#This Row],[Salaire Brut de référence]]*4/10),0))))) -> 0 | AI8: =IF(TPersonnel[[#This Row],[INDEM LÉGALE]]=0,"",IF(TPersonnel[[#This Row],[INDEM LÉGALE]]>TPersonnel[[#This Row],[INDEM CONV.]],"LEGAL","CONVENTIONNEL")) | AJ8: =MAX(TPersonnel[[#This Row],[INDEM LÉGALE]],TPersonnel[[#This Row],[INDEM CONV.]]) -> 0 | AK8: =TPersonnel[[#This Row],[INDEM RETENUE]]*'⚙️ Parametres'!$B$5 -> 0 | AL8: =TPersonnel[[#This Row],[INDEM RETENUE]]+TPersonnel[[#This Row],[Majoration PSE]] -> 0 | AM8: =IF(UPPER(TPersonnel[[#This Row],[Fonction à supprimer]])="NON",0,IF(OR(TPersonnel[[#This Row],[Catégorie]]="Cadre"),3,IF(TPersonnel[[#This Row],[Catégorie]]="Haute maitrise",2,IF(OR(TPersonnel[[#This Row],[Catégorie]]="Agent Maitrise",TPersonnel[[#This Row],[Catégorie]]="Agent de maitrise"),IF(TPersonnel[[#This Row],[Ancienneté (ans) à la date théorique de sortie]]<2/12,0,IF(TPersonnel[[#This Row],[Ancienneté (ans) à la date théorique de sortie]]<2,1,2)),IF(OR(TPersonnel[[#This Row],[Catégorie]]="Ouvrier",TPersonnel[[#This Row],[Catégorie]]="Employe",TPersonnel[[#This Row],[Catégorie]]="Employé"),IF(TPersonnel[[#This Row],[Ancienneté (ans) à la date théorique de sortie]]<6/12,IF(TPersonnel[[#This Row],[Catégorie]]="Ouvrier",1/4,IF(TPersonnel[[#This Row],[Ancienneté (ans) à la date théorique de sortie]]<1/12,0,1)),IF(TPersonnel[[#This Row],[Ancienneté (ans) à la date théorique de sortie]]<2,1,2)),2))))) -> 0 | AN8: =IF(UPPER(TPersonnel[[#This Row],[Fonction à supprimer]])="NON",0,TPersonnel[[#This Row],[Préavis Calc (mois)]]*TPersonnel[[#This Row],[Salaire Brut de référence]]) -> 0 | AO8: =IF(TPersonnel[[#This Row],[Fonction à supprimer]]="NON",0,TPersonnel[[#This Row],[Nb CP Acquis]]+TPersonnel[[#This Row],[Préavis Calc (mois)]]*2.08) -> 0 | AP8: =TPersonnel[[#This Row],[CP Calc (jrs)]]*TPersonnel[[#This Row],[Salaire Brut de référence]]/21.67 -> 0 | AQ8: =IF(UPPER(TPersonnel[[#This Row],[Fonction à supprimer]])="NON",0,_xlfn.LET(_xlpm.taux,IF(TPersonnel[[#This Row],[Catégorie]]="Ouvrier",'📈 Dashboard'!$B$32,IF(TPersonnel[[#This Row],[Catégorie]]="Cadre",'📈 Dashboard'!$B$34,'📈 Dashboard'!$B$33)),_xlpm.csp,UPPER(TPersonnel[[#This Row],[CSP (contrat de sécurisation professionnel)]])="OUI",IF(AND(_xlpm.csp,TPersonnel[[#This Row],[Ancienneté (ans) à la date théorique de sortie]]>=1),MIN(TPersonnel[[#This Row],[Préavis Calc (mois)]],3)*TPersonnel[[#This Row],[Salaire Brut de référence]]*(_xlpm.taux+'⚙️ Parametres'!$B$11)+IF(TPersonnel[[#This Row],[Préavis Calc (mois)]]>3,(TPersonnel[[#This Row],[Préavis Calc (mois)]]-3)*TPersonnel[[#This Row],[Salaire Brut de référence]]*_xlpm.taux,0)+TPersonnel[[#This Row],[Indem CP]]*_xlpm.taux,IF(_xlpm.csp,TPersonnel[[#This Row],[Indem CP]]*_xlpm.taux,(TPersonnel[[#This Row],[Indem Préavis Brut]]+TPersonnel[[#This Row],[Indem CP]])*_xlpm.taux)))) -> 0 | AR8: =TPersonnel[[#This Row],[TOTAL INDEM]]+TPersonnel[[#This Row],[Indem Préavis Brut]]+TPersonnel[[#This Row],[Indem CP]]+TPersonnel[[#This Row],[COÛT Charges Patronales]] -> 0
A9: 28 | B9: Non | C9: BENSID AHMED | D9: Ali | E9: VALENCE | F9: Chauffeur PL | G9: CDI | H9: Ouvrier | I9: 150M | J9: H | K9: 39301 | L9: 39301 | M9: 29066 | N9: 3110.06 | P9: 17.58 | Q9: =IF(UPPER(B9)="OUI",'📈 Dashboard'!$B$37,"") | R9: =MAX(N9,O9/12) -> 3110.06 | S9: 2616.89 | T9: =IF(L9="",(TODAY()-K9)/365.25,MAX((TODAY()-K9)/365.25,(TODAY()-L9)/365.25)) -> 18.606434 | U9: =IF(M9="","",(TODAY()-M9)/365.25) -> 46.628337 | V9: =N9*12 -> 37320.72 | W9: =IF(H9="Cadre",3,IF(H9="Haute maitrise",2,IF(OR(H9="Agent Maitrise",H9="Agent de maitrise"),IF(T9<2/12,0,IF(T9<2,1,2)),IF(OR(H9="Ouvrier"),IF(T9<6/12,1/4,IF(T9<2,1,2)),IF(OR(H9="Employe",H9="Employé"),IF(T9<1/12,0,IF(T9<2,1,2)),2))))) -> 2 | X9: =IF(Q9="",T9,(Q9-K9)/365.25) -> 18.606434 | AG9: =IF(TPersonnel[[#This Row],[Fonction à supprimer]]="NON",0,IF(TPersonnel[[#This Row],[Ancienneté (ans) à la date théorique de sortie]]<0.67,0,IF(TPersonnel[[#This Row],[Ancienneté (ans) à la date théorique de sortie]]<=10,TPersonnel[[#This Row],[Ancienneté (ans) à la date théorique de sortie]]*TPersonnel[[#This Row],[Salaire Brut de référence]]/4,(10*TPersonnel[[#This Row],[Salaire Brut de référence]]/4+(TPersonnel[[#This Row],[Ancienneté (ans) à la date théorique de sortie]]-10)*TPersonnel[[#This Row],[Salaire Brut de référence]]/3)))) -> 0 | AH9: =IF(UPPER(TPersonnel[[#This Row],[Fonction à supprimer]])="NON",0,IF(TPersonnel[[#This Row],[Ancienneté (ans) à la date théorique de sortie]]<1,0,IF(OR(TPersonnel[[#This Row],[Catégorie]]="Ouvrier",TPersonnel[[#This Row],[Catégorie]]="Employe",TPersonnel[[#This Row],[Catégorie]]="Employé"),IF(TPersonnel[[#This Row],[Ancienneté (ans) à la date théorique de sortie]]<3,TPersonnel[[#This Row],[Ancienneté (ans) à la date théorique de sortie]]*TPersonnel[[#This Row],[Salaire Brut de référence]]/10,TPersonnel[[#This Row],[Ancienneté (ans) à la date théorique de sortie]]*TPersonnel[[#This Row],[Salaire Brut de référence]]*2/10),IF(OR(TPersonnel[[#This Row],[Catégorie]]="Agent Maitrise",TPersonnel[[#This Row],[Catégorie]]="Agent de maitrise",TPersonnel[[#This Row],[Catégorie]]="Haute maitrise"),IF(TPersonnel[[#This Row],[Ancienneté (ans) à la date théorique de sortie]]<3,TPersonnel[[#This Row],[Ancienneté (ans) à la date théorique de sortie]]*TPersonnel[[#This Row],[Salaire Brut de référence]]/10,TPersonnel[[#This Row],[Ancienneté (ans) à la date théorique de sortie]]*TPersonnel[[#This Row],[Salaire Brut de référence]]*3/10),IF(TPersonnel[[#This Row],[Catégorie]]="Cadre",IF(TPersonnel[[#This Row],[Ancienneté (ans) à la date théorique de sortie]]<3,0,TPersonnel[[#This Row],[Ancienneté (ans) à la date théorique de sortie]]*TPersonnel[[#This Row],[Salaire Brut de référence]]*4/10),0))))) -> 0 | AI9: =IF(TPersonnel[[#This Row],[INDEM LÉGALE]]=0,"",IF(TPersonnel[[#This Row],[INDEM LÉGALE]]>TPersonnel[[#This Row],[INDEM CONV.]],"LEGAL","CONVENTIONNEL")) | AJ9: =MAX(TPersonnel[[#This Row],[INDEM LÉGALE]],TPersonnel[[#This Row],[INDEM CONV.]]) -> 0 | AK9: =TPersonnel[[#This Row],[INDEM RETENUE]]*'⚙️ Parametres'!$B$5 -> 0 | AL9: =TPersonnel[[#This Row],[INDEM RETENUE]]+TPersonnel[[#This Row],[Majoration PSE]] -> 0 | AM9: =IF(UPPER(TPersonnel[[#This Row],[Fonction à supprimer]])="NON",0,IF(OR(TPersonnel[[#This Row],[Catégorie]]="Cadre"),3,IF(TPersonnel[[#This Row],[Catégorie]]="Haute maitrise",2,IF(OR(TPersonnel[[#This Row],[Catégorie]]="Agent Maitrise",TPersonnel[[#This Row],[Catégorie]]="Agent de maitrise"),IF(TPersonnel[[#This Row],[Ancienneté (ans) à la date théorique de sortie]]<2/12,0,IF(TPersonnel[[#This Row],[Ancienneté (ans) à la date théorique de sortie]]<2,1,2)),IF(OR(TPersonnel[[#This Row],[Catégorie]]="Ouvrier",TPersonnel[[#This Row],[Catégorie]]="Employe",TPersonnel[[#This Row],[Catégorie]]="Employé"),IF(TPersonnel[[#This Row],[Ancienneté (ans) à la date théorique de sortie]]<6/12,IF(TPersonnel[[#This Row],[Catégorie]]="Ouvrier",1/4,IF(TPersonnel[[#This Row],[Ancienneté (ans) à la date théorique de sortie]]<1/12,0,1)),IF(TPersonnel[[#This Row],[Ancienneté (ans) à la date théorique de sortie]]<2,1,2)),2))))) -> 0 | AN9: =IF(UPPER(TPersonnel[[#This Row],[Fonction à supprimer]])="NON",0,TPersonnel[[#This Row],[Préavis Calc (mois)]]*TPersonnel[[#This Row],[Salaire Brut de référence]]) -> 0 | AO9: =IF(TPersonnel[[#This Row],[Fonction à supprimer]]="NON",0,TPersonnel[[#This Row],[Nb CP Acquis]]+TPersonnel[[#This Row],[Préavis Calc (mois)]]*2.08) -> 0 | AP9: =TPersonnel[[#This Row],[CP Calc (jrs)]]*TPersonnel[[#This Row],[Salaire Brut de référence]]/21.67 -> 0 | AQ9: =IF(UPPER(TPersonnel[[#This Row],[Fonction à supprimer]])="NON",0,_xlfn.LET(_xlpm.taux,IF(TPersonnel[[#This Row],[Catégorie]]="Ouvrier",'📈 Dashboard'!$B$32,IF(TPersonnel[[#This Row],[Catégorie]]="Cadre",'📈 Dashboard'!$B$34,'📈 Dashboard'!$B$33)),_xlpm.csp,UPPER(TPersonnel[[#This Row],[CSP (contrat de sécurisation professionnel)]])="OUI",IF(AND(_xlpm.csp,TPersonnel[[#This Row],[Ancienneté (ans) à la date théorique de sortie]]>=1),MIN(TPersonnel[[#This Row],[Préavis Calc (mois)]],3)*TPersonnel[[#This Row],[Salaire Brut de référence]]*(_xlpm.taux+'⚙️ Parametres'!$B$11)+IF(TPersonnel[[#This Row],[Préavis Calc (mois)]]>3,(TPersonnel[[#This Row],[Préavis Calc (mois)]]-3)*TPersonnel[[#This Row],[Salaire Brut de référence]]*_xlpm.taux,0)+TPersonnel[[#This Row],[Indem CP]]*_xlpm.taux,IF(_xlpm.csp,TPersonnel[[#This Row],[Indem CP]]*_xlpm.taux,(TPersonnel[[#This Row],[Indem Préavis Brut]]+TPersonnel[[#This Row],[Indem CP]])*_xlpm.taux)))) -> 0 | AR9: =TPersonnel[[#This Row],[TOTAL INDEM]]+TPersonnel[[#This Row],[Indem Préavis Brut]]+TPersonnel[[#This Row],[Indem CP]]+TPersonnel[[#This Row],[COÛT Charges Patronales]] -> 0
A10: 31 | B10: Non | C10: BOULAKHSOUMI | D10: Mostafa | E10: VALENCE | F10: Resp Exploitation | G10: CDI | H10: Agent de maîtrise | I10: 185 | J10: H | K10: 42107 | L10: 42107 | M10: 24222 | N10: 3250 | P10: 51.58 | Q10: =IF(UPPER(B10)="OUI",'📈 Dashboard'!$B$37,"") | R10: =MAX(N10,O10/12) -> 3250 | S10: 7735.79 | T10: =IF(L10="",(TODAY()-K10)/365.25,MAX((TODAY()-K10)/365.25,(TODAY()-L10)/365.25)) -> 10.924025 | U10: =IF(M10="","",(TODAY()-M10)/365.25) -> 59.890486 | V10: =N10*12 -> 39000 | W10: =IF(H10="Cadre",3,IF(H10="Haute maitrise",2,IF(OR(H10="Agent Maitrise",H10="Agent de maitrise"),IF(T10<2/12,0,IF(T10<2,1,2)),IF(OR(H10="Ouvrier"),IF(T10<6/12,1/4,IF(T10<2,1,2)),IF(OR(H10="Employe",H10="Employé"),IF(T10<1/12,0,IF(T10<2,1,2)),2))))) -> 2 | X10: =IF(Q10="",T10,(Q10-K10)/365.25) -> 10.924025 | AG10: =IF(TPersonnel[[#This Row],[Fonction à supprimer]]="NON",0,IF(TPersonnel[[#This Row],[Ancienneté (ans) à la date théorique de sortie]]<0.67,0,IF(TPersonnel[[#This Row],[Ancienneté (ans) à la date théorique de sortie]]<=10,TPersonnel[[#This Row],[Ancienneté (ans) à la date théorique de sortie]]*TPersonnel[[#This Row],[Salaire Brut de référence]]/4,(10*TPersonnel[[#This Row],[Salaire Brut de référence]]/4+(TPersonnel[[#This Row],[Ancienneté (ans) à la date théorique de sortie]]-10)*TPersonnel[[#This Row],[Salaire Brut de référence]]/3)))) -> 0 | AH10: =IF(UPPER(TPersonnel[[#This Row],[Fonction à supprimer]])="NON",0,IF(TPersonnel[[#This Row],[Ancienneté (ans) à la date théorique de sortie]]<1,0,IF(OR(TPersonnel[[#This Row],[Catégorie]]="Ouvrier",TPersonnel[[#This Row],[Catégorie]]="Employe",TPersonnel[[#This Row],[Catégorie]]="Employé"),IF(TPersonnel[[#This Row],[Ancienneté (ans) à la date théorique de sortie]]<3,TPersonnel[[#This Row],[Ancienneté (ans) à la date théorique de sortie]]*TPersonnel[[#This Row],[Salaire Brut de référence]]/10,TPersonnel[[#This Row],[Ancienneté (ans) à la date théorique de sortie]]*TPersonnel[[#This Row],[Salaire Brut de référence]]*2/10),IF(OR(TPersonnel[[#This Row],[Catégorie]]="Agent Maitrise",TPersonnel[[#This Row],[Catégorie]]="Agent de maitrise",TPersonnel[[#This Row],[Catégorie]]="Haute maitrise"),IF(TPersonnel[[#This Row],[Ancienneté (ans) à la date théorique de sortie]]<3,TPersonnel[[#This Row],[Ancienneté (ans) à la date théorique de sortie]]*TPersonnel[[#This Row],[Salaire Brut de référence]]/10,TPersonnel[[#This Row],[Ancienneté (ans) à la date théorique de sortie]]*TPersonnel[[#This Row],[Salaire Brut de référence]]*3/10),IF(TPersonnel[[#This Row],[Catégorie]]="Cadre",IF(TPersonnel[[#This Row],[Ancienneté (ans) à la date théorique de sortie]]<3,0,TPersonnel[[#This Row],[Ancienneté (ans) à la date théorique de sortie]]*TPersonnel[[#This Row],[Salaire Brut de référence]]*4/10),0))))) -> 0 | AI10: =IF(TPersonnel[[#This Row],[INDEM LÉGALE]]=0,"",IF(TPersonnel[[#This Row],[INDEM LÉGALE]]>TPersonnel[[#This Row],[INDEM CONV.]],"LEGAL","CONVENTIONNEL")) | AJ10: =MAX(TPersonnel[[#This Row],[INDEM LÉGALE]],TPersonnel[[#This Row],[INDEM CONV.]]) -> 0 | AK10: =TPersonnel[[#This Row],[INDEM RETENUE]]*'⚙️ Parametres'!$B$5 -> 0 | AL10: =TPersonnel[[#This Row],[INDEM RETENUE]]+TPersonnel[[#This Row],[Majoration PSE]] -> 0 | AM10: =IF(UPPER(TPersonnel[[#This Row],[Fonction à supprimer]])="NON",0,IF(OR(TPersonnel[[#This Row],[Catégorie]]="Cadre"),3,IF(TPersonnel[[#This Row],[Catégorie]]="Haute maitrise",2,IF(OR(TPersonnel[[#This Row],[Catégorie]]="Agent Maitrise",TPersonnel[[#This Row],[Catégorie]]="Agent de maitrise"),IF(TPersonnel[[#This Row],[Ancienneté (ans) à la date théorique de sortie]]<2/12,0,IF(TPersonnel[[#This Row],[Ancienneté (ans) à la date théorique de sortie]]<2,1,2)),IF(OR(TPersonnel[[#This Row],[Catégorie]]="Ouvrier",TPersonnel[[#This Row],[Catégorie]]="Employe",TPersonnel[[#This Row],[Catégorie]]="Employé"),IF(TPersonnel[[#This Row],[Ancienneté (ans) à la date théorique de sortie]]<6/12,IF(TPersonnel[[#This Row],[Catégorie]]="Ouvrier",1/4,IF(TPersonnel[[#This Row],[Ancienneté (ans) à la date théorique de sortie]]<1/12,0,1)),IF(TPersonnel[[#This Row],[Ancienneté (ans) à la date théorique de sortie]]<2,1,2)),2))))) -> 0 | AN10: =IF(UPPER(TPersonnel[[#This Row],[Fonction à supprimer]])="NON",0,TPersonnel[[#This Row],[Préavis Calc (mois)]]*TPersonnel[[#This Row],[Salaire Brut de référence]]) -> 0 | AO10: =IF(TPersonnel[[#This Row],[Fonction à supprimer]]="NON",0,TPersonnel[[#This Row],[Nb CP Acquis]]+TPersonnel[[#This Row],[Préavis Calc (mois)]]*2.08) -> 0 | AP10: =TPersonnel[[#This Row],[CP Calc (jrs)]]*TPersonnel[[#This Row],[Salaire Brut de référence]]/21.67 -> 0 | AQ10: =IF(UPPER(TPersonnel[[#This Row],[Fonction à supprimer]])="NON",0,_xlfn.LET(_xlpm.taux,IF(TPersonnel[[#This Row],[Catégorie]]="Ouvrier",'📈 Dashboard'!$B$32,IF(TPersonnel[[#This Row],[Catégorie]]="Cadre",'📈 Dashboard'!$B$34,'📈 Dashboard'!$B$33)),_xlpm.csp,UPPER(TPersonnel[[#This Row],[CSP (contrat de sécurisation professionnel)]])="OUI",IF(AND(_xlpm.csp,TPersonnel[[#This Row],[Ancienneté (ans) à la date théorique de sortie]]>=1),MIN(TPersonnel[[#This Row],[Préavis Calc (mois)]],3)*TPersonnel[[#This Row],[Salaire Brut de référence]]*(_xlpm.taux+'⚙️ Parametres'!$B$11)+IF(TPersonnel[[#This Row],[Préavis Calc (mois)]]>3,(TPersonnel[[#This Row],[Préavis Calc (mois)]]-3)*TPersonnel[[#This Row],[Salaire Brut de référence]]*_xlpm.taux,0)+TPersonnel[[#This Row],[Indem CP]]*_xlpm.taux,IF(_xlpm.csp,TPersonnel[[#This Row],[Indem CP]]*_xlpm.taux,(TPersonnel[[#This Row],[Indem Préavis Brut]]+TPersonnel[[#This Row],[Indem CP]])*_xlpm.taux)))) -> 0 | AR10: =TPersonnel[[#This Row],[TOTAL INDEM]]+TPersonnel[[#This Row],[Indem Préavis Brut]]+TPersonnel[[#This Row],[Indem CP]]+TPersonnel[[#This Row],[COÛT Charges Patronales]] -> 0
A11: 33 | B11: Non | C11: HAOUARI | D11: Khaled | E11: VALENCE | F11: Chauffeur PL | G11: CDI | H11: Ouvrier | I11: 150M | J11: H | K11: 39182 | L11: 39182 | M11: 24037 | N11: 2827.92 | P11: 13.58 | Q11: =IF(UPPER(B11)="OUI",'📈 Dashboard'!$B$37,"") | R11: =MAX(N11,O11/12) -> 2827.92 | S11: 1852.93 | T11: =IF(L11="",(TODAY()-K11)/365.25,MAX((TODAY()-K11)/365.25,(TODAY()-L11)/365.25)) -> 18.932238 | U11: =IF(M11="","",(TODAY()-M11)/365.25) -> 60.396988 | V11: =N11*12 -> 33935.04 | W11: =IF(H11="Cadre",3,IF(H11="Haute maitrise",2,IF(OR(H11="Agent Maitrise",H11="Agent de maitrise"),IF(T11<2/12,0,IF(T11<2,1,2)),IF(OR(H11="Ouvrier"),IF(T11<6/12,1/4,IF(T11<2,1,2)),IF(OR(H11="Employe",H11="Employé"),IF(T11<1/12,0,IF(T11<2,1,2)),2))))) -> 2 | X11: =IF(Q11="",T11,(Q11-K11)/365.25) -> 18.932238 | AG11: =IF(TPersonnel[[#This Row],[Fonction à supprimer]]="NON",0,IF(TPersonnel[[#This Row],[Ancienneté (ans) à la date théorique de sortie]]<0.67,0,IF(TPersonnel[[#This Row],[Ancienneté (ans) à la date théorique de sortie]]<=10,TPersonnel[[#This Row],[Ancienneté (ans) à la date théorique de sortie]]*TPersonnel[[#This Row],[Salaire Brut de référence]]/4,(10*TPersonnel[[#This Row],[Salaire Brut de référence]]/4+(TPersonnel[[#This Row],[Ancienneté (ans) à la date théorique de sortie]]-10)*TPersonnel[[#This Row],[Salaire Brut de référence]]/3)))) -> 0 | AH11: =IF(UPPER(TPersonnel[[#This Row],[Fonction à supprimer]])="NON",0,IF(TPersonnel[[#This Row],[Ancienneté (ans) à la date théorique de sortie]]<1,0,IF(OR(TPersonnel[[#This Row],[Catégorie]]="Ouvrier",TPersonnel[[#This Row],[Catégorie]]="Employe",TPersonnel[[#This Row],[Catégorie]]="Employé"),IF(TPersonnel[[#This Row],[Ancienneté (ans) à la date théorique de sortie]]<3,TPersonnel[[#This Row],[Ancienneté (ans) à la date théorique de sortie]]*TPersonnel[[#This Row],[Salaire Brut de référence]]/10,TPersonnel[[#This Row],[Ancienneté (ans) à la date théorique de sortie]]*TPersonnel[[#This Row],[Salaire Brut de référence]]*2/10),IF(OR(TPersonnel[[#This Row],[Catégorie]]="Agent Maitrise",TPersonnel[[#This Row],[Catégorie]]="Agent de maitrise",TPersonnel[[#This Row],[Catégorie]]="Haute maitrise"),IF(TPersonnel[[#This Row],[Ancienneté (ans) à la date théorique de sortie]]<3,TPersonnel[[#This Row],[Ancienneté (ans) à la date théorique de sortie]]*TPersonnel[[#This Row],[Salaire Brut de référence]]/10,TPersonnel[[#This Row],[Ancienneté (ans) à la date théorique de sortie]]*TPersonnel[[#This Row],[Salaire Brut de référence]]*3/10),IF(TPersonnel[[#This Row],[Catégorie]]="Cadre",IF(TPersonnel[[#This Row],[Ancienneté (ans) à la date théorique de sortie]]<3,0,TPersonnel[[#This Row],[Ancienneté (ans) à la date théorique de sortie]]*TPersonnel[[#This Row],[Salaire Brut de référence]]*4/10),0))))) -> 0 | AI11: =IF(TPersonnel[[#This Row],[INDEM LÉGALE]]=0,"",IF(TPersonnel[[#This Row],[INDEM LÉGALE]]>TPersonnel[[#This Row],[INDEM CONV.]],"LEGAL","CONVENTIONNEL")) | AJ11: =MAX(TPersonnel[[#This Row],[INDEM LÉGALE]],TPersonnel[[#This Row],[INDEM CONV.]]) -> 0 | AK11: =TPersonnel[[#This Row],[INDEM RETENUE]]*'⚙️ Parametres'!$B$5 -> 0 | AL11: =TPersonnel[[#This Row],[INDEM RETENUE]]+TPersonnel[[#This Row],[Majoration PSE]] -> 0 | AM11: =IF(UPPER(TPersonnel[[#This Row],[Fonction à supprimer]])="NON",0,IF(OR(TPersonnel[[#This Row],[Catégorie]]="Cadre"),3,IF(TPersonnel[[#This Row],[Catégorie]]="Haute maitrise",2,IF(OR(TPersonnel[[#This Row],[Catégorie]]="Agent Maitrise",TPersonnel[[#This Row],[Catégorie]]="Agent de maitrise"),IF(TPersonnel[[#This Row],[Ancienneté (ans) à la date théorique de sortie]]<2/12,0,IF(TPersonnel[[#This Row],[Ancienneté (ans) à la date théorique de sortie]]<2,1,2)),IF(OR(TPersonnel[[#This Row],[Catégorie]]="Ouvrier",TPersonnel[[#This Row],[Catégorie]]="Employe",TPersonnel[[#This Row],[Catégorie]]="Employé"),IF(TPersonnel[[#This Row],[Ancienneté (ans) à la date théorique de sortie]]<6/12,IF(TPersonnel[[#This Row],[Catégorie]]="Ouvrier",1/4,IF(TPersonnel[[#This Row],[Ancienneté (ans) à la date théorique de sortie]]<1/12,0,1)),IF(TPersonnel[[#This Row],[Ancienneté (ans) à la date théorique de sortie]]<2,1,2)),2))))) -> 0 | AN11: =IF(UPPER(TPersonnel[[#This Row],[Fonction à supprimer]])="NON",0,TPersonnel[[#This Row],[Préavis Calc (mois)]]*TPersonnel[[#This Row],[Salaire Brut de référence]]) -> 0 | AO11: =IF(TPersonnel[[#This Row],[Fonction à supprimer]]="NON",0,TPersonnel[[#This Row],[Nb CP Acquis]]+TPersonnel[[#This Row],[Préavis Calc (mois)]]*2.08) -> 0 | AP11: =TPersonnel[[#This Row],[CP Calc (jrs)]]*TPersonnel[[#This Row],[Salaire Brut de référence]]/21.67 -> 0 | AQ11: =IF(UPPER(TPersonnel[[#This Row],[Fonction à supprimer]])="NON",0,_xlfn.LET(_xlpm.taux,IF(TPersonnel[[#This Row],[Catégorie]]="Ouvrier",'📈 Dashboard'!$B$32,IF(TPersonnel[[#This Row],[Catégorie]]="Cadre",'📈 Dashboard'!$B$34,'📈 Dashboard'!$B$33)),_xlpm.csp,UPPER(TPersonnel[[#This Row],[CSP (contrat de sécurisation professionnel)]])="OUI",IF(AND(_xlpm.csp,TPersonnel[[#This Row],[Ancienneté (ans) à la date théorique de sortie]]>=1),MIN(TPersonnel[[#This Row],[Préavis Calc (mois)]],3)*TPersonnel[[#This Row],[Salaire Brut de référence]]*(_xlpm.taux+'⚙️ Parametres'!$B$11)+IF(TPersonnel[[#This Row],[Préavis Calc (mois)]]>3,(TPersonnel[[#This Row],[Préavis Calc (mois)]]-3)*TPersonnel[[#This Row],[Salaire Brut de référence]]*_xlpm.taux,0)+TPersonnel[[#This Row],[Indem CP]]*_xlpm.taux,IF(_xlpm.csp,TPersonnel[[#This Row],[Indem CP]]*_xlpm.taux,(TPersonnel[[#This Row],[Indem Préavis Brut]]+TPersonnel[[#This Row],[Indem CP]])*_xlpm.taux)))) -> 0 | AR11: =TPersonnel[[#This Row],[TOTAL INDEM]]+TPersonnel[[#This Row],[Indem Préavis Brut]]+TPersonnel[[#This Row],[Indem CP]]+TPersonnel[[#This Row],[COÛT Charges Patronales]] -> 0
A12: 35 | B12: Non | C12: GUENIFI | D12: Abdelkader | E12: VALENCE | F12: Chauffeur SPL | G12: CDI | H12: Ouvrier | I12: 138M | J12: H | K12: 41673 | L12: 41673 | M12: 31288 | N12: 2842.93 | P12: 18.53 | Q12: =IF(UPPER(B12)="OUI",'📈 Dashboard'!$B$37,"") | R12: =MAX(N12,O12/12) -> 2842.93 | S12: 2773.39 | T12: =IF(L12="",(TODAY()-K12)/365.25,MAX((TODAY()-K12)/365.25,(TODAY()-L12)/365.25)) -> 12.112252 | U12: =IF(M12="","",(TODAY()-M12)/365.25) -> 40.544832 | V12: =N12*12 -> 34115.16 | W12: =IF(H12="Cadre",3,IF(H12="Haute maitrise",2,IF(OR(H12="Agent Maitrise",H12="Agent de maitrise"),IF(T12<2/12,0,IF(T12<2,1,2)),IF(OR(H12="Ouvrier"),IF(T12<6/12,1/4,IF(T12<2,1,2)),IF(OR(H12="Employe",H12="Employé"),IF(T12<1/12,0,IF(T12<2,1,2)),2))))) -> 2 | X12: =IF(Q12="",T12,(Q12-K12)/365.25) -> 12.112252 | AG12: =IF(TPersonnel[[#This Row],[Fonction à supprimer]]="NON",0,IF(TPersonnel[[#This Row],[Ancienneté (ans) à la date théorique de sortie]]<0.67,0,IF(TPersonnel[[#This Row],[Ancienneté (ans) à la date théorique de sortie]]<=10,TPersonnel[[#This Row],[Ancienneté (ans) à la date théorique de sortie]]*TPersonnel[[#This Row],[Salaire Brut de référence]]/4,(10*TPersonnel[[#This Row],[Salaire Brut de référence]]/4+(TPersonnel[[#This Row],[Ancienneté (ans) à la date théorique de sortie]]-10)*TPersonnel[[#This Row],[Salaire Brut de référence]]/3)))) -> 0 | AH12: =IF(UPPER(TPersonnel[[#This Row],[Fonction à supprimer]])="NON",0,IF(TPersonnel[[#This Row],[Ancienneté (ans) à la date théorique de sortie]]<1,0,IF(OR(TPersonnel[[#This Row],[Catégorie]]="Ouvrier",TPersonnel[[#This Row],[Catégorie]]="Employe",TPersonnel[[#This Row],[Catégorie]]="Employé"),IF(TPersonnel[[#This Row],[Ancienneté (ans) à la date théorique de sortie]]<3,TPersonnel[[#This Row],[Ancienneté (ans) à la date théorique de sortie]]*TPersonnel[[#This Row],[Salaire Brut de référence]]/10,TPersonnel[[#This Row],[Ancienneté (ans) à la date théorique de sortie]]*TPersonnel[[#This Row],[Salaire Brut de référence]]*2/10),IF(OR(TPersonnel[[#This Row],[Catégorie]]="Agent Maitrise",TPersonnel[[#This Row],[Catégorie]]="Agent de maitrise",TPersonnel[[#This Row],[Catégorie]]="Haute maitrise"),IF(TPersonnel[[#This Row],[Ancienneté (ans) à la date théorique de sortie]]<3,TPersonnel[[#This Row],[Ancienneté (ans) à la date théorique de sortie]]*TPersonnel[[#This Row],[Salaire Brut de référence]]/10,TPersonnel[[#This Row],[Ancienneté (ans) à la date théorique de sortie]]*TPersonnel[[#This Row],[Salaire Brut de référence]]*3/10),IF(TPersonnel[[#This Row],[Catégorie]]="Cadre",IF(TPersonnel[[#This Row],[Ancienneté (ans) à la date théorique de sortie]]<3,0,TPersonnel[[#This Row],[Ancienneté (ans) à la date théorique de sortie]]*TPersonnel[[#This Row],[Salaire Brut de référence]]*4/10),0))))) -> 0 | AI12: =IF(TPersonnel[[#This Row],[INDEM LÉGALE]]=0,"",IF(TPersonnel[[#This Row],[INDEM LÉGALE]]>TPersonnel[[#This Row],[INDEM CONV.]],"LEGAL","CONVENTIONNEL")) | AJ12: =MAX(TPersonnel[[#This Row],[INDEM LÉGALE]],TPersonnel[[#This Row],[INDEM CONV.]]) -> 0 | AK12: =TPersonnel[[#This Row],[INDEM RETENUE]]*'⚙️ Parametres'!$B$5 -> 0 | AL12: =TPersonnel[[#This Row],[INDEM RETENUE]]+TPersonnel[[#This Row],[Majoration PSE]] -> 0 | AM12: =IF(UPPER(TPersonnel[[#This Row],[Fonction à supprimer]])="NON",0,IF(OR(TPersonnel[[#This Row],[Catégorie]]="Cadre"),3,IF(TPersonnel[[#This Row],[Catégorie]]="Haute maitrise",2,IF(OR(TPersonnel[[#This Row],[Catégorie]]="Agent Maitrise",TPersonnel[[#This Row],[Catégorie]]="Agent de maitrise"),IF(TPersonnel[[#This Row],[Ancienneté (ans) à la date théorique de sortie]]<2/12,0,IF(TPersonnel[[#This Row],[Ancienneté (ans) à la date théorique de sortie]]<2,1,2)),IF(OR(TPersonnel[[#This Row],[Catégorie]]="Ouvrier",TPersonnel[[#This Row],[Catégorie]]="Employe",TPersonnel[[#This Row],[Catégorie]]="Employé"),IF(TPersonnel[[#This Row],[Ancienneté (ans) à la date théorique de sortie]]<6/12,IF(TPersonnel[[#This Row],[Catégorie]]="Ouvrier",1/4,IF(TPersonnel[[#This Row],[Ancienneté (ans) à la date théorique de sortie]]<1/12,0,1)),IF(TPersonnel[[#This Row],[Ancienneté (ans) à la date théorique de sortie]]<2,1,2)),2))))) -> 0 | AN12: =IF(UPPER(TPersonnel[[#This Row],[Fonction à supprimer]])="NON",0,TPersonnel[[#This Row],[Préavis Calc (mois)]]*TPersonnel[[#This Row],[Salaire Brut de référence]]) -> 0 | AO12: =IF(TPersonnel[[#This Row],[Fonction à supprimer]]="NON",0,TPersonnel[[#This Row],[Nb CP Acquis]]+TPersonnel[[#This Row],[Préavis Calc (mois)]]*2.08) -> 0 | AP12: =TPersonnel[[#This Row],[CP Calc (jrs)]]*TPersonnel[[#This Row],[Salaire Brut de référence]]/21.67 -> 0 | AQ12: =IF(UPPER(TPersonnel[[#This Row],[Fonction à supprimer]])="NON",0,_xlfn.LET(_xlpm.taux,IF(TPersonnel[[#This Row],[Catégorie]]="Ouvrier",'📈 Dashboard'!$B$32,IF(TPersonnel[[#This Row],[Catégorie]]="Cadre",'📈 Dashboard'!$B$34,'📈 Dashboard'!$B$33)),_xlpm.csp,UPPER(TPersonnel[[#This Row],[CSP (contrat de sécurisation professionnel)]])="OUI",IF(AND(_xlpm.csp,TPersonnel[[#This Row],[Ancienneté (ans) à la date théorique de sortie]]>=1),MIN(TPersonnel[[#This Row],[Préavis Calc (mois)]],3)*TPersonnel[[#This Row],[Salaire Brut de référence]]*(_xlpm.taux+'⚙️ Parametres'!$B$11)+IF(TPersonnel[[#This Row],[Préavis Calc (mois)]]>3,(TPersonnel[[#This Row],[Préavis Calc (mois)]]-3)*TPersonnel[[#This Row],[Salaire Brut de référence]]*_xlpm.taux,0)+TPersonnel[[#This Row],[Indem CP]]*_xlpm.taux,IF(_xlpm.csp,TPersonnel[[#This Row],[Indem CP]]*_xlpm.taux,(TPersonnel[[#This Row],[Indem Préavis Brut]]+TPersonnel[[#This Row],[Indem CP]])*_xlpm.taux)))) -> 0 | AR12: =TPersonnel[[#This Row],[TOTAL INDEM]]+TPersonnel[[#This Row],[Indem Préavis Brut]]+TPersonnel[[#This Row],[Indem CP]]+TPersonnel[[#This Row],[COÛT Charges Patronales]] -> 0
A13: 40 | B13: Non | C13: TESTARD | D13: Jean-Claude | E13: VALENCE | F13: Chauffeur PL | G13: CDI | H13: Ouvrier | I13: 150M | J13: H | K13: 41334 | L13: 33512 | M13: 24052 | N13: 2974.39 | P13: 25.58 | Q13: =IF(UPPER(B13)="OUI",'📈 Dashboard'!$B$37,"") | R13: =MAX(N13,O13/12) -> 2974.39 | S13: 3650.41 | T13: =IF(L13="",(TODAY()-K13)/365.25,MAX((TODAY()-K13)/365.25,(TODAY()-L13)/365.25)) -> 34.455852 | U13: =IF(M13="","",(TODAY()-M13)/365.25) -> 60.355921 | V13: =N13*12 -> 35692.68 | W13: =IF(H13="Cadre",3,IF(H13="Haute maitrise",2,IF(OR(H13="Agent Maitrise",H13="Agent de maitrise"),IF(T13<2/12,0,IF(T13<2,1,2)),IF(OR(H13="Ouvrier"),IF(T13<6/12,1/4,IF(T13<2,1,2)),IF(OR(H13="Employe",H13="Employé"),IF(T13<1/12,0,IF(T13<2,1,2)),2))))) -> 2 | X13: =IF(Q13="",T13,(Q13-K13)/365.25) -> 34.455852 | AG13: =IF(TPersonnel[[#This Row],[Fonction à supprimer]]="NON",0,IF(TPersonnel[[#This Row],[Ancienneté (ans) à la date théorique de sortie]]<0.67,0,IF(TPersonnel[[#This Row],[Ancienneté (ans) à la date théorique de sortie]]<=10,TPersonnel[[#This Row],[Ancienneté (ans) à la date théorique de sortie]]*TPersonnel[[#This Row],[Salaire Brut de référence]]/4,(10*TPersonnel[[#This Row],[Salaire Brut de référence]]/4+(TPersonnel[[#This Row],[Ancienneté (ans) à la date théorique de sortie]]-10)*TPersonnel[[#This Row],[Salaire Brut de référence]]/3)))) -> 0 | AH13: =IF(UPPER(TPersonnel[[#This Row],[Fonction à supprimer]])="NON",0,IF(TPersonnel[[#This Row],[Ancienneté (ans) à la date théorique de sortie]]<1,0,IF(OR(TPersonnel[[#This Row],[Catégorie]]="Ouvrier",TPersonnel[[#This Row],[Catégorie]]="Employe",TPersonnel[[#This Row],[Catégorie]]="Employé"),IF(TPersonnel[[#This Row],[Ancienneté (ans) à la date théorique de sortie]]<3,TPersonnel[[#This Row],[Ancienneté (ans) à la date théorique de sortie]]*TPersonnel[[#This Row],[Salaire Brut de référence]]/10,TPersonnel[[#This Row],[Ancienneté (ans) à la date théorique de sortie]]*TPersonnel[[#This Row],[Salaire Brut de référence]]*2/10),IF(OR(TPersonnel[[#This Row],[Catégorie]]="Agent Maitrise",TPersonnel[[#This Row],[Catégorie]]="Agent de maitrise",TPersonnel[[#This Row],[Catégorie]]="Haute maitrise"),IF(TPersonnel[[#This Row],[Ancienneté (ans) à la date théorique de sortie]]<3,TPersonnel[[#This Row],[Ancienneté (ans) à la date théorique de sortie]]*TPersonnel[[#This Row],[Salaire Brut de référence]]/10,TPersonnel[[#This Row],[Ancienneté (ans) à la date théorique de sortie]]*TPersonnel[[#This Row],[Salaire Brut de référence]]*3/10),IF(TPersonnel[[#This Row],[Catégorie]]="Cadre",IF(TPersonnel[[#This Row],[Ancienneté (ans) à la date théorique de sortie]]<3,0,TPersonnel[[#This Row],[Ancienneté (ans) à la date théorique de sortie]]*TPersonnel[[#This Row],[Salaire Brut de référence]]*4/10),0))))) -> 0 | AI13: =IF(TPersonnel[[#This Row],[INDEM LÉGALE]]=0,"",IF(TPersonnel[[#This Row],[INDEM LÉGALE]]>TPersonnel[[#This Row],[INDEM CONV.]],"LEGAL","CONVENTIONNEL")) | AJ13: =MAX(TPersonnel[[#This Row],[INDEM LÉGALE]],TPersonnel[[#This Row],[INDEM CONV.]]) -> 0 | AK13: =TPersonnel[[#This Row],[INDEM RETENUE]]*'⚙️ Parametres'!$B$5 -> 0 | AL13: =TPersonnel[[#This Row],[INDEM RETENUE]]+TPersonnel[[#This Row],[Majoration PSE]] -> 0 | AM13: =IF(UPPER(TPersonnel[[#This Row],[Fonction à supprimer]])="NON",0,IF(OR(TPersonnel[[#This Row],[Catégorie]]="Cadre"),3,IF(TPersonnel[[#This Row],[Catégorie]]="Haute maitrise",2,IF(OR(TPersonnel[[#This Row],[Catégorie]]="Agent Maitrise",TPersonnel[[#This Row],[Catégorie]]="Agent de maitrise"),IF(TPersonnel[[#This Row],[Ancienneté (ans) à la date théorique de sortie]]<2/12,0,IF(TPersonnel[[#This Row],[Ancienneté (ans) à la date théorique de sortie]]<2,1,2)),IF(OR(TPersonnel[[#This Row],[Catégorie]]="Ouvrier",TPersonnel[[#This Row],[Catégorie]]="Employe",TPersonnel[[#This Row],[Catégorie]]="Employé"),IF(TPersonnel[[#This Row],[Ancienneté (ans) à la date théorique de sortie]]<6/12,IF(TPersonnel[[#This Row],[Catégorie]]="Ouvrier",1/4,IF(TPersonnel[[#This Row],[Ancienneté (ans) à la date théorique de sortie]]<1/12,0,1)),IF(TPersonnel[[#This Row],[Ancienneté (ans) à la date théorique de sortie]]<2,1,2)),2))))) -> 0 | AN13: =IF(UPPER(TPersonnel[[#This Row],[Fonction à supprimer]])="NON",0,TPersonnel[[#This Row],[Préavis Calc (mois)]]*TPersonnel[[#This Row],[Salaire Brut de référence]]) -> 0 | AO13: =IF(TPersonnel[[#This Row],[Fonction à supprimer]]="NON",0,TPersonnel[[#This Row],[Nb CP Acquis]]+TPersonnel[[#This Row],[Préavis Calc (mois)]]*2.08) -> 0 | AP13: =TPersonnel[[#This Row],[CP Calc (jrs)]]*TPersonnel[[#This Row],[Salaire Brut de référence]]/21.67 -> 0 | AQ13: =IF(UPPER(TPersonnel[[#This Row],[Fonction à supprimer]])="NON",0,_xlfn.LET(_xlpm.taux,IF(TPersonnel[[#This Row],[Catégorie]]="Ouvrier",'📈 Dashboard'!$B$32,IF(TPersonnel[[#This Row],[Catégorie]]="Cadre",'📈 Dashboard'!$B$34,'📈 Dashboard'!$B$33)),_xlpm.csp,UPPER(TPersonnel[[#This Row],[CSP (contrat de sécurisation professionnel)]])="OUI",IF(AND(_xlpm.csp,TPersonnel[[#This Row],[Ancienneté (ans) à la date théorique de sortie]]>=1),MIN(TPersonnel[[#This Row],[Préavis Calc (mois)]],3)*TPersonnel[[#This Row],[Salaire Brut de référence]]*(_xlpm.taux+'⚙️ Parametres'!$B$11)+IF(TPersonnel[[#This Row],[Préavis Calc (mois)]]>3,(TPersonnel[[#This Row],[Préavis Calc (mois)]]-3)*TPersonnel[[#This Row],[Salaire Brut de référence]]*_xlpm.taux,0)+TPersonnel[[#This Row],[Indem CP]]*_xlpm.taux,IF(_xlpm.csp,TPersonnel[[#This Row],[Indem CP]]*_xlpm.taux,(TPersonnel[[#This Row],[Indem Préavis Brut]]+TPersonnel[[#This Row],[Indem CP]])*_xlpm.taux)))) -> 0 | AR13: =TPersonnel[[#This Row],[TOTAL INDEM]]+TPersonnel[[#This Row],[Indem Préavis Brut]]+TPersonnel[[#This Row],[Indem CP]]+TPersonnel[[#This Row],[COÛT Charges Patronales]] -> 0
